Workbook

Sheet Hướng dẫn
A1: CHECKLIST TỰ ĐÁNH GIÁ AN NINH MẠNG HTTT THEO CẤP ĐỘ (TCVN 14423:2026)
A2: Tóm lược để tra cứu; khi lập hồ sơ phải đối chiếu bản chính thức TCVN 14423:2026 (mua tại VSQI). Cột yêu cầu là diễn giải ngắn, không phải nguyên văn tiêu chuẩn.
A4: Tổ chức (chủ quản) | B4: {{TEN_TO_CHUC}}
A5: Hệ thống thông tin | B5: {{TEN_HE_THONG}}
A6: Cấp độ | B6: {{CAP_DO}}
A7: Người đánh giá (bộ phận độc lập — NĐ 331 Đ31.2.c) | B7: {{DON_VI_DANH_GIA_DOC_LAP}}
A8: Ngày đánh giá
A10: 1. Chọn sheet đúng cấp độ của hệ thống (Cấp 1 … Cấp 5). Mỗi dòng là một yêu cầu TCVN, tóm lược.
A11: 2. Ô tô vàng là ô cần điền. Cột 'Kết quả' chọn từ danh sách: Đạt · Một phần · Chưa · N/A.
A12: 3. Mọi N/A phải ghi lý do ở cột 'Ghi chú'; dùng phương án tương đương thì mô tả biện pháp thay thế.
A13: 4. Dòng 'Chưa' / 'Một phần': ghi Người phụ trách và Hạn khắc phục — đây là kế hoạch khắc phục trong hồ sơ cấp độ.
A14: 5. Sheet 'Tổng hợp' tự tính theo công thức; % Đạt = Đạt / (Tổng số dòng − N/A).
A15: 6. Cột 'Ghi chú' có sẵn nhãn 'Mới/khác so với cấp N-1' để thấy phần tăng thêm khi nâng cấp.
A16: Nguồn: docs/03-yeu-cau-theo-cap-do/checklist-cap-*.md (repo vn-cyber-compliance). Căn cứ: NĐ 331/2026/NĐ-CP Đ28.4, Đ29.1, Đ30.1.
A18: Ví dụ một dòng đã điền:
A19: Mục TCVN | B19: Yêu cầu (tóm lược) | C19: Kết quả | D19: Bằng chứng cần lưu | E19: Ghi chú | F19: Người phụ trách | G19: Hạn khắc phục
A20: 5.6.2.4 | B20: Xác thực đa yếu tố cho tài khoản quản trị | C20: Một phần | D20: Ảnh cấu hình MFA trên cổng quản trị | E20: Chưa áp dụng cho truy cập SSH | F20: {{DON_VI_VAN_HANH}} | G20: 30/11/2026

Sheet Tổng hợp
A1: TỔNG HỢP KẾT QUẢ TỰ ĐÁNH GIÁ
A2: Tự tính từ các sheet Cấp 1–5. % Đạt = Đạt / (Tổng − N/A).
A4: Cấp độ | B4: Nhóm | C4: Tên nhóm | D4: Số yêu cầu | E4: Đạt | F4: Một phần | G4: Chưa | H4: N/A | I4: Chưa điền | J4: % Đạt
A5: Cấp 1 | B5: 3.1 | C5: Quản lý rủi ro an ninh mạng | D5: =COUNTIFS('Cấp 1'!$A$5:$A$113,B5) | E5: =COUNTIFS('Cấp 1'!$A$5:$A$113,B5,'Cấp 1'!$E$5:$E$113,"Đạt") | F5: =COUNTIFS('Cấp 1'!$A$5:$A$113,B5,'Cấp 1'!$E$5:$E$113,"Một phần") | G5: =COUNTIFS('Cấp 1'!$A$5:$A$113,B5,'Cấp 1'!$E$5:$E$113,"Chưa") | H5: =COUNTIFS('Cấp 1'!$A$5:$A$113,B5,'Cấp 1'!$E$5:$E$113,"N/A") | I5: =D5-SUM(E5:H5) | J5: =IF(D5-H5=0,"",E5/(D5-H5))
A6: Cấp 1 | B6: 3.2 | C6: Quản lý tài sản phần cứng | D6: =COUNTIFS('Cấp 1'!$A$5:$A$113,B6) | E6: =COUNTIFS('Cấp 1'!$A$5:$A$113,B6,'Cấp 1'!$E$5:$E$113,"Đạt") | F6: =COUNTIFS('Cấp 1'!$A$5:$A$113,B6,'Cấp 1'!$E$5:$E$113,"Một phần") | G6: =COUNTIFS('Cấp 1'!$A$5:$A$113,B6,'Cấp 1'!$E$5:$E$113,"Chưa") | H6: =COUNTIFS('Cấp 1'!$A$5:$A$113,B6,'Cấp 1'!$E$5:$E$113,"N/A") | I6: =D6-SUM(E6:H6) | J6: =IF(D6-H6=0,"",E6/(D6-H6))
A7: Cấp 1 | B7: 3.3 | C7: Quản lý tài sản phần mềm | D7: =COUNTIFS('Cấp 1'!$A$5:$A$113,B7) | E7: =COUNTIFS('Cấp 1'!$A$5:$A$113,B7,'Cấp 1'!$E$5:$E$113,"Đạt") | F7: =COUNTIFS('Cấp 1'!$A$5:$A$113,B7,'Cấp 1'!$E$5:$E$113,"Một phần") | G7: =COUNTIFS('Cấp 1'!$A$5:$A$113,B7,'Cấp 1'!$E$5:$E$113,"Chưa") | H7: =COUNTIFS('Cấp 1'!$A$5:$A$113,B7,'Cấp 1'!$E$5:$E$113,"N/A") | I7: =D7-SUM(E7:H7) | J7: =IF(D7-H7=0,"",E7/(D7-H7))
A8: Cấp 1 | B8: 3.4 | C8: Quản lý tài sản thông tin | D8: =COUNTIFS('Cấp 1'!$A$5:$A$113,B8) | E8: =COUNTIFS('Cấp 1'!$A$5:$A$113,B8,'Cấp 1'!$E$5:$E$113,"Đạt") | F8: =COUNTIFS('Cấp 1'!$A$5:$A$113,B8,'Cấp 1'!$E$5:$E$113,"Một phần") | G8: =COUNTIFS('Cấp 1'!$A$5:$A$113,B8,'Cấp 1'!$E$5:$E$113,"Chưa") | H8: =COUNTIFS('Cấp 1'!$A$5:$A$113,B8,'Cấp 1'!$E$5:$E$113,"N/A") | I8: =D8-SUM(E8:H8) | J8: =IF(D8-H8=0,"",E8/(D8-H8))
A9: Cấp 1 | B9: 3.5 | C9: Cấu hình an toàn phần cứng, phần mềm | D9: =COUNTIFS('Cấp 1'!$A$5:$A$113,B9) | E9: =COUNTIFS('Cấp 1'!$A$5:$A$113,B9,'Cấp 1'!$E$5:$E$113,"Đạt") | F9: =COUNTIFS('Cấp 1'!$A$5:$A$113,B9,'Cấp 1'!$E$5:$E$113,"Một phần") | G9: =COUNTIFS('Cấp 1'!$A$5:$A$113,B9,'Cấp 1'!$E$5:$E$113,"Chưa") | H9: =COUNTIFS('Cấp 1'!$A$5:$A$113,B9,'Cấp 1'!$E$5:$E$113,"N/A") | I9: =D9-SUM(E9:H9) | J9: =IF(D9-H9=0,"",E9/(D9-H9))
A10: Cấp 1 | B10: 3.6 | C10: Quản lý tài khoản và quyền truy cập | D10: =COUNTIFS('Cấp 1'!$A$5:$A$113,B10) | E10: =COUNTIFS('Cấp 1'!$A$5:$A$113,B10,'Cấp 1'!$E$5:$E$113,"Đạt") | F10: =COUNTIFS('Cấp 1'!$A$5:$A$113,B10,'Cấp 1'!$E$5:$E$113,"Một phần") | G10: =COUNTIFS('Cấp 1'!$A$5:$A$113,B10,'Cấp 1'!$E$5:$E$113,"Chưa") | H10: =COUNTIFS('Cấp 1'!$A$5:$A$113,B10,'Cấp 1'!$E$5:$E$113,"N/A") | I10: =D10-SUM(E10:H10) | J10: =IF(D10-H10=0,"",E10/(D10-H10))
A11: Cấp 1 | B11: 3.7 | C11: Quản lý lỗ hổng bảo mật | D11: =COUNTIFS('Cấp 1'!$A$5:$A$113,B11) | E11: =COUNTIFS('Cấp 1'!$A$5:$A$113,B11,'Cấp 1'!$E$5:$E$113,"Đạt") | F11: =COUNTIFS('Cấp 1'!$A$5:$A$113,B11,'Cấp 1'!$E$5:$E$113,"Một phần") | G11: =COUNTIFS('Cấp 1'!$A$5:$A$113,B11,'Cấp 1'!$E$5:$E$113,"Chưa") | H11: =COUNTIFS('Cấp 1'!$A$5:$A$113,B11,'Cấp 1'!$E$5:$E$113,"N/A") | I11: =D11-SUM(E11:H11) | J11: =IF(D11-H11=0,"",E11/(D11-H11))
A12: Cấp 1 | B12: 3.8 | C12: Quản lý nhật ký an ninh mạng | D12: =COUNTIFS('Cấp 1'!$A$5:$A$113,B12) | E12: =COUNTIFS('Cấp 1'!$A$5:$A$113,B12,'Cấp 1'!$E$5:$E$113,"Đạt") | F12: =COUNTIFS('Cấp 1'!$A$5:$A$113,B12,'Cấp 1'!$E$5:$E$113,"Một phần") | G12: =COUNTIFS('Cấp 1'!$A$5:$A$113,B12,'Cấp 1'!$E$5:$E$113,"Chưa") | H12: =COUNTIFS('Cấp 1'!$A$5:$A$113,B12,'Cấp 1'!$E$5:$E$113,"N/A") | I12: =D12-SUM(E12:H12) | J12: =IF(D12-H12=0,"",E12/(D12-H12))
A13: Cấp 1 | B13: 3.9 | C13: Bảo vệ trình duyệt web, thư điện tử | D13: =COUNTIFS('Cấp 1'!$A$5:$A$113,B13) | E13: =COUNTIFS('Cấp 1'!$A$5:$A$113,B13,'Cấp 1'!$E$5:$E$113,"Đạt") | F13: =COUNTIFS('Cấp 1'!$A$5:$A$113,B13,'Cấp 1'!$E$5:$E$113,"Một phần") | G13: =COUNTIFS('Cấp 1'!$A$5:$A$113,B13,'Cấp 1'!$E$5:$E$113,"Chưa") | H13: =COUNTIFS('Cấp 1'!$A$5:$A$113,B13,'Cấp 1'!$E$5:$E$113,"N/A") | I13: =D13-SUM(E13:H13) | J13: =IF(D13-H13=0,"",E13/(D13-H13))
A14: Cấp 1 | B14: 3.10 | C14: Phòng chống phần mềm độc hại | D14: =COUNTIFS('Cấp 1'!$A$5:$A$113,B14) | E14: =COUNTIFS('Cấp 1'!$A$5:$A$113,B14,'Cấp 1'!$E$5:$E$113,"Đạt") | F14: =COUNTIFS('Cấp 1'!$A$5:$A$113,B14,'Cấp 1'!$E$5:$E$113,"Một phần") | G14: =COUNTIFS('Cấp 1'!$A$5:$A$113,B14,'Cấp 1'!$E$5:$E$113,"Chưa") | H14: =COUNTIFS('Cấp 1'!$A$5:$A$113,B14,'Cấp 1'!$E$5:$E$113,"N/A") | I14: =D14-SUM(E14:H14) | J14: =IF(D14-H14=0,"",E14/(D14-H14))
A15: Cấp 1 | B15: 3.11 | C15: Sao lưu và khôi phục dữ liệu | D15: =COUNTIFS('Cấp 1'!$A$5:$A$113,B15) | E15: =COUNTIFS('Cấp 1'!$A$5:$A$113,B15,'Cấp 1'!$E$5:$E$113,"Đạt") | F15: =COUNTIFS('Cấp 1'!$A$5:$A$113,B15,'Cấp 1'!$E$5:$E$113,"Một phần") | G15: =COUNTIFS('Cấp 1'!$A$5:$A$113,B15,'Cấp 1'!$E$5:$E$113,"Chưa") | H15: =COUNTIFS('Cấp 1'!$A$5:$A$113,B15,'Cấp 1'!$E$5:$E$113,"N/A") | I15: =D15-SUM(E15:H15) | J15: =IF(D15-H15=0,"",E15/(D15-H15))
A16: Cấp 1 | B16: 3.12 | C16: Quản lý hạ tầng mạng | D16: =COUNTIFS('Cấp 1'!$A$5:$A$113,B16) | E16: =COUNTIFS('Cấp 1'!$A$5:$A$113,B16,'Cấp 1'!$E$5:$E$113,"Đạt") | F16: =COUNTIFS('Cấp 1'!$A$5:$A$113,B16,'Cấp 1'!$E$5:$E$113,"Một phần") | G16: =COUNTIFS('Cấp 1'!$A$5:$A$113,B16,'Cấp 1'!$E$5:$E$113,"Chưa") | H16: =COUNTIFS('Cấp 1'!$A$5:$A$113,B16,'Cấp 1'!$E$5:$E$113,"N/A") | I16: =D16-SUM(E16:H16) | J16: =IF(D16-H16=0,"",E16/(D16-H16))
... A19: Cấp 1 | B19: 3.15 | C19: Quản trị ứng phó sự cố an ninh mạng | D19: =COUNTIFS('Cấp 1'!$A$5:$A$113,B19) | E19: =COUNTIFS('Cấp 1'!$A$5:$A$113,B19,'Cấp 1'!$E$5:$E$113,"Đạt") | F19: =COUNTIFS('Cấp 1'!$A$5:$A$113,B19,'Cấp 1'!$E$5:$E$113,"Một phần") | G19: =COUNTIFS('Cấp 1'!$A$5:$A$113,B19,'Cấp 1'!$E$5:$E$113,"Chưa") | H19: =COUNTIFS('Cấp 1'!$A$5:$A$113,B19,'Cấp 1'!$E$5:$E$113,"N/A") | I19: =D19-SUM(E19:H19) | J19: =IF(D19-H19=0,"",E19/(D19-H19))
A20: Cấp 1 | C20: Tổng | D20: =SUM(D5:D19) | E20: =SUM(E5:E19) | F20: =SUM(F5:F19) | G20: =SUM(G5:G19) | H20: =SUM(H5:H19) | I20: =SUM(I5:I19) | J20: =IF(D20-H20=0,"",E20/(D20-H20))
A22: Cấp độ | B22: Nhóm | C22: Tên nhóm | D22: Số yêu cầu | E22: Đạt | F22: Một phần | G22: Chưa | H22: N/A | I22: Chưa điền | J22: % Đạt
A23: Cấp 2 | B23: 4.1 | C23: Quản lý rủi ro an ninh mạng | D23: =COUNTIFS('Cấp 2'!$A$5:$A$133,B23) | E23: =COUNTIFS('Cấp 2'!$A$5:$A$133,B23,'Cấp 2'!$E$5:$E$133,"Đạt") | F23: =COUNTIFS('Cấp 2'!$A$5:$A$133,B23,'Cấp 2'!$E$5:$E$133,"Một phần") | G23: =COUNTIFS('Cấp 2'!$A$5:$A$133,B23,'Cấp 2'!$E$5:$E$133,"Chưa") | H23: =COUNTIFS('Cấp 2'!$A$5:$A$133,B23,'Cấp 2'!$E$5:$E$133,"N/A") | I23: =D23-SUM(E23:H23) | J23: =IF(D23-H23=0,"",E23/(D23-H23))
A24: Cấp 2 | B24: 4.2 | C24: Quản lý tài sản phần cứng | D24: =COUNTIFS('Cấp 2'!$A$5:$A$133,B24) | E24: =COUNTIFS('Cấp 2'!$A$5:$A$133,B24,'Cấp 2'!$E$5:$E$133,"Đạt") | F24: =COUNTIFS('Cấp 2'!$A$5:$A$133,B24,'Cấp 2'!$E$5:$E$133,"Một phần") | G24: =COUNTIFS('Cấp 2'!$A$5:$A$133,B24,'Cấp 2'!$E$5:$E$133,"Chưa") | H24: =COUNTIFS('Cấp 2'!$A$5:$A$133,B24,'Cấp 2'!$E$5:$E$133,"N/A") | I24: =D24-SUM(E24:H24) | J24: =IF(D24-H24=0,"",E24/(D24-H24))
A25: Cấp 2 | B25: 4.3 | C25: Quản lý tài sản phần mềm | D25: =COUNTIFS('Cấp 2'!$A$5:$A$133,B25) | E25: =COUNTIFS('Cấp 2'!$A$5:$A$133,B25,'Cấp 2'!$E$5:$E$133,"Đạt") | F25: =COUNTIFS('Cấp 2'!$A$5:$A$133,B25,'Cấp 2'!$E$5:$E$133,"Một phần") | G25: =COUNTIFS('Cấp 2'!$A$5:$A$133,B25,'Cấp 2'!$E$5:$E$133,"Chưa") | H25: =COUNTIFS('Cấp 2'!$A$5:$A$133,B25,'Cấp 2'!$E$5:$E$133,"N/A") | I25: =D25-SUM(E25:H25) | J25: =IF(D25-H25=0,"",E25/(D25-H25))
A26: Cấp 2 | B26: 4.4 | C26: Quản lý tài sản thông tin | D26: =COUNTIFS('Cấp 2'!$A$5:$A$133,B26) | E26: =COUNTIFS('Cấp 2'!$A$5:$A$133,B26,'Cấp 2'!$E$5:$E$133,"Đạt") | F26: =COUNTIFS('Cấp 2'!$A$5:$A$133,B26,'Cấp 2'!$E$5:$E$133,"Một phần") | G26: =COUNTIFS('Cấp 2'!$A$5:$A$133,B26,'Cấp 2'!$E$5:$E$133,"Chưa") | H26: =COUNTIFS('Cấp 2'!$A$5:$A$133,B26,'Cấp 2'!$E$5:$E$133,"N/A") | I26: =D26-SUM(E26:H26) | J26: =IF(D26-H26=0,"",E26/(D26-H26))
A27: Cấp 2 | B27: 4.5 | C27: Cấu hình an toàn phần cứng, phần mềm | D27: =COUNTIFS('Cấp 2'!$A$5:$A$133,B27) | E27: =COUNTIFS('Cấp 2'!$A$5:$A$133,B27,'Cấp 2'!$E$5:$E$133,"Đạt") | F27: =COUNTIFS('Cấp 2'!$A$5:$A$133,B27,'Cấp 2'!$E$5:$E$133,"Một phần") | G27: =COUNTIFS('Cấp 2'!$A$5:$A$133,B27,'Cấp 2'!$E$5:$E$133,"Chưa") | H27: =COUNTIFS('Cấp 2'!$A$5:$A$133,B27,'Cấp 2'!$E$5:$E$133,"N/A") | I27: =D27-SUM(E27:H27) | J27: =IF(D27-H27=0,"",E27/(D27-H27))
A28: Cấp 2 | B28: 4.6 | C28: Quản lý tài khoản và quyền truy cập | D28: =COUNTIFS('Cấp 2'!$A$5:$A$133,B28) | E28: =COUNTIFS('Cấp 2'!$A$5:$A$133,B28,'Cấp 2'!$E$5:$E$133,"Đạt") | F28: =COUNTIFS('Cấp 2'!$A$5:$A$133,B28,'Cấp 2'!$E$5:$E$133,"Một phần") | G28: =COUNTIFS('Cấp 2'!$A$5:$A$133,B28,'Cấp 2'!$E$5:$E$133,"Chưa") | H28: =COUNTIFS('Cấp 2'!$A$5:$A$133,B28,'Cấp 2'!$E$5:$E$133,"N/A") | I28: =D28-SUM(E28:H28) | J28: =IF(D28-H28=0,"",E28/(D28-H28))
A29: Cấp 2 | B29: 4.7 | C29: Quản lý lỗ hổng bảo mật | D29: =COUNTIFS('Cấp 2'!$A$5:$A$133,B29) | E29: =COUNTIFS('Cấp 2'!$A$5:$A$133,B29,'Cấp 2'!$E$5:$E$133,"Đạt") | F29: =COUNTIFS('Cấp 2'!$A$5:$A$133,B29,'Cấp 2'!$E$5:$E$133,"Một phần") | G29: =COUNTIFS('Cấp 2'!$A$5:$A$133,B29,'Cấp 2'!$E$5:$E$133,"Chưa") | H29: =COUNTIFS('Cấp 2'!$A$5:$A$133,B29,'Cấp 2'!$E$5:$E$133,"N/A") | I29: =D29-SUM(E29:H29) | J29: =IF(D29-H29=0,"",E29/(D29-H29))
A30: Cấp 2 | B30: 4.8 | C30: Quản lý nhật ký an ninh mạng | D30: =COUNTIFS('Cấp 2'!$A$5:$A$133,B30) | E30: =COUNTIFS('Cấp 2'!$A$5:$A$133,B30,'Cấp 2'!$E$5:$E$133,"Đạt") | F30: =COUNTIFS('Cấp 2'!$A$5:$A$133,B30,'Cấp 2'!$E$5:$E$133,"Một phần") | G30: =COUNTIFS('Cấp 2'!$A$5:$A$133,B30,'Cấp 2'!$E$5:$E$133,"Chưa") | H30: =COUNTIFS('Cấp 2'!$A$5:$A$133,B30,'Cấp 2'!$E$5:$E$133,"N/A") | I30: =D30-SUM(E30:H30) | J30: =IF(D30-H30=0,"",E30/(D30-H30))
A31: Cấp 2 | B31: 4.9 | C31: Bảo vệ trình duyệt web, thư điện tử | D31: =COUNTIFS('Cấp 2'!$A$5:$A$133,B31) | E31: =COUNTIFS('Cấp 2'!$A$5:$A$133,B31,'Cấp 2'!$E$5:$E$133,"Đạt") | F31: =COUNTIFS('Cấp 2'!$A$5:$A$133,B31,'Cấp 2'!$E$5:$E$133,"Một phần") | G31: =COUNTIFS('Cấp 2'!$A$5:$A$133,B31,'Cấp 2'!$E$5:$E$133,"Chưa") | H31: =COUNTIFS('Cấp 2'!$A$5:$A$133,B31,'Cấp 2'!$E$5:$E$133,"N/A") | I31: =D31-SUM(E31:H31) | J31: =IF(D31-H31=0,"",E31/(D31-H31))
A32: Cấp 2 | B32: 4.10 | C32: Phòng chống phần mềm độc hại | D32: =COUNTIFS('Cấp 2'!$A$5:$A$133,B32) | E32: =COUNTIFS('Cấp 2'!$A$5:$A$133,B32,'Cấp 2'!$E$5:$E$133,"Đạt") | F32: =COUNTIFS('Cấp 2'!$A$5:$A$133,B32,'Cấp 2'!$E$5:$E$133,"Một phần") | G32: =COUNTIFS('Cấp 2'!$A$5:$A$133,B32,'Cấp 2'!$E$5:$E$133,"Chưa") | H32: =COUNTIFS('Cấp 2'!$A$5:$A$133,B32,'Cấp 2'!$E$5:$E$133,"N/A") | I32: =D32-SUM(E32:H32) | J32: =IF(D32-H32=0,"",E32/(D32-H32))
A33: Cấp 2 | B33: 4.11 | C33: Sao lưu và khôi phục dữ liệu | D33: =COUNTIFS('Cấp 2'!$A$5:$A$133,B33) | E33: =COUNTIFS('Cấp 2'!$A$5:$A$133,B33,'Cấp 2'!$E$5:$E$133,"Đạt") | F33: =COUNTIFS('Cấp 2'!$A$5:$A$133,B33,'Cấp 2'!$E$5:$E$133,"Một phần") | G33: =COUNTIFS('Cấp 2'!$A$5:$A$133,B33,'Cấp 2'!$E$5:$E$133,"Chưa") | H33: =COUNTIFS('Cấp 2'!$A$5:$A$133,B33,'Cấp 2'!$E$5:$E$133,"N/A") | I33: =D33-SUM(E33:H33) | J33: =IF(D33-H33=0,"",E33/(D33-H33))
A34: Cấp 2 | B34: 4.12 | C34: Quản lý hạ tầng mạng | D34: =COUNTIFS('Cấp 2'!$A$5:$A$133,B34) | E34: =COUNTIFS('Cấp 2'!$A$5:$A$133,B34,'Cấp 2'!$E$5:$E$133,"Đạt") | F34: =COUNTIFS('Cấp 2'!$A$5:$A$133,B34,'Cấp 2'!$E$5:$E$133,"Một phần") | G34: =COUNTIFS('Cấp 2'!$A$5:$A$133,B34,'Cấp 2'!$E$5:$E$133,"Chưa") | H34: =COUNTIFS('Cấp 2'!$A$5:$A$133,B34,'Cấp 2'!$E$5:$E$133,"N/A") | I34: =D34-SUM(E34:H34) | J34: =IF(D34-H34=0,"",E34/(D34-H34))
... A37: Cấp 2 | B37: 4.15 | C37: Quản trị ứng phó sự cố an ninh mạng | D37: =COUNTIFS('Cấp 2'!$A$5:$A$133,B37) | E37: =COUNTIFS('Cấp 2'!$A$5:$A$133,B37,'Cấp 2'!$E$5:$E$133,"Đạt") | F37: =COUNTIFS('Cấp 2'!$A$5:$A$133,B37,'Cấp 2'!$E$5:$E$133,"Một phần") | G37: =COUNTIFS('Cấp 2'!$A$5:$A$133,B37,'Cấp 2'!$E$5:$E$133,"Chưa") | H37: =COUNTIFS('Cấp 2'!$A$5:$A$133,B37,'Cấp 2'!$E$5:$E$133,"N/A") | I37: =D37-SUM(E37:H37) | J37: =IF(D37-H37=0,"",E37/(D37-H37))
A38: Cấp 2 | C38: Tổng | D38: =SUM(D23:D37) | E38: =SUM(E23:E37) | F38: =SUM(F23:F37) | G38: =SUM(G23:G37) | H38: =SUM(H23:H37) | I38: =SUM(I23:I37) | J38: =IF(D38-H38=0,"",E38/(D38-H38))
A40: Cấp độ | B40: Nhóm | C40: Tên nhóm | D40: Số yêu cầu | E40: Đạt | F40: Một phần | G40: Chưa | H40: N/A | I40: Chưa điền | J40: % Đạt
A41: Cấp 3 | B41: 5.1 | C41: Quản lý rủi ro an ninh mạng | D41: =COUNTIFS('Cấp 3'!$A$5:$A$199,B41) | E41: =COUNTIFS('Cấp 3'!$A$5:$A$199,B41,'Cấp 3'!$E$5:$E$199,"Đạt") | F41: =COUNTIFS('Cấp 3'!$A$5:$A$199,B41,'Cấp 3'!$E$5:$E$199,"Một phần") | G41: =COUNTIFS('Cấp 3'!$A$5:$A$199,B41,'Cấp 3'!$E$5:$E$199,"Chưa") | H41: =COUNTIFS('Cấp 3'!$A$5:$A$199,B41,'Cấp 3'!$E$5:$E$199,"N/A") | I41: =D41-SUM(E41:H41) | J41: =IF(D41-H41=0,"",E41/(D41-H41))
A42: Cấp 3 | B42: 5.2 | C42: Quản lý tài sản phần cứng | D42: =COUNTIFS('Cấp 3'!$A$5:$A$199,B42) | E42: =COUNTIFS('Cấp 3'!$A$5:$A$199,B42,'Cấp 3'!$E$5:$E$199,"Đạt") | F42: =COUNTIFS('Cấp 3'!$A$5:$A$199,B42,'Cấp 3'!$E$5:$E$199,"Một phần") | G42: =COUNTIFS('Cấp 3'!$A$5:$A$199,B42,'Cấp 3'!$E$5:$E$199,"Chưa") | H42: =COUNTIFS('Cấp 3'!$A$5:$A$199,B42,'Cấp 3'!$E$5:$E$199,"N/A") | I42: =D42-SUM(E42:H42) | J42: =IF(D42-H42=0,"",E42/(D42-H42))
A43: Cấp 3 | B43: 5.3 | C43: Quản lý tài sản phần mềm | D43: =COUNTIFS('Cấp 3'!$A$5:$A$199,B43) | E43: =COUNTIFS('Cấp 3'!$A$5:$A$199,B43,'Cấp 3'!$E$5:$E$199,"Đạt") | F43: =COUNTIFS('Cấp 3'!$A$5:$A$199,B43,'Cấp 3'!$E$5:$E$199,"Một phần") | G43: =COUNTIFS('Cấp 3'!$A$5:$A$199,B43,'Cấp 3'!$E$5:$E$199,"Chưa") | H43: =COUNTIFS('Cấp 3'!$A$5:$A$199,B43,'Cấp 3'!$E$5:$E$199,"N/A") | I43: =D43-SUM(E43:H43) | J43: =IF(D43-H43=0,"",E43/(D43-H43))
A44: Cấp 3 | B44: 5.4 | C44: Quản lý tài sản thông tin | D44: =COUNTIFS('Cấp 3'!$A$5:$A$199,B44) | E44: =COUNTIFS('Cấp 3'!$A$5:$A$199,B44,'Cấp 3'!$E$5:$E$199,"Đạt") | F44: =COUNTIFS('Cấp 3'!$A$5:$A$199,B44,'Cấp 3'!$E$5:$E$199,"Một phần") | G44: =COUNTIFS('Cấp 3'!$A$5:$A$199,B44,'Cấp 3'!$E$5:$E$199,"Chưa") | H44: =COUNTIFS('Cấp 3'!$A$5:$A$199,B44,'Cấp 3'!$E$5:$E$199,"N/A") | I44: =D44-SUM(E44:H44) | J44: =IF(D44-H44=0,"",E44/(D44-H44))
A45: Cấp 3 | B45: 5.5 | C45: Cấu hình an toàn phần cứng, phần mềm | D45: =COUNTIFS('Cấp 3'!$A$5:$A$199,B45) | E45: =COUNTIFS('Cấp 3'!$A$5:$A$199,B45,'Cấp 3'!$E$5:$E$199,"Đạt") | F45: =COUNTIFS('Cấp 3'!$A$5:$A$199,B45,'Cấp 3'!$E$5:$E$199,"Một phần") | G45: =COUNTIFS('Cấp 3'!$A$5:$A$199,B45,'Cấp 3'!$E$5:$E$199,"Chưa") | H45: =COUNTIFS('Cấp 3'!$A$5:$A$199,B45,'Cấp 3'!$E$5:$E$199,"N/A") | I45: =D45-SUM(E45:H45) | J45: =IF(D45-H45=0,"",E45/(D45-H45))
A46: Cấp 3 | B46: 5.6 | C46: Quản lý tài khoản và quyền truy cập | D46: =COUNTIFS('Cấp 3'!$A$5:$A$199,B46) | E46: =COUNTIFS('Cấp 3'!$A$5:$A$199,B46,'Cấp 3'!$E$5:$E$199,"Đạt") | F46: =COUNTIFS('Cấp 3'!$A$5:$A$199,B46,'Cấp 3'!$E$5:$E$199,"Một phần") | G46: =COUNTIFS('Cấp 3'!$A$5:$A$199,B46,'Cấp 3'!$E$5:$E$199,"Chưa") | H46: =COUNTIFS('Cấp 3'!$A$5:$A$199,B46,'Cấp 3'!$E$5:$E$199,"N/A") | I46: =D46-SUM(E46:H46) | J46: =IF(D46-H46=0,"",E46/(D46-H46))
A47: Cấp 3 | B47: 5.7 | C47: Quản lý lỗ hổng bảo mật | D47: =COUNTIFS('Cấp 3'!$A$5:$A$199,B47) | E47: =COUNTIFS('Cấp 3'!$A$5:$A$199,B47,'Cấp 3'!$E$5:$E$199,"Đạt") | F47: =COUNTIFS('Cấp 3'!$A$5:$A$199,B47,'Cấp 3'!$E$5:$E$199,"Một phần") | G47: =COUNTIFS('Cấp 3'!$A$5:$A$199,B47,'Cấp 3'!$E$5:$E$199,"Chưa") | H47: =COUNTIFS('Cấp 3'!$A$5:$A$199,B47,'Cấp 3'!$E$5:$E$199,"N/A") | I47: =D47-SUM(E47:H47) | J47: =IF(D47-H47=0,"",E47/(D47-H47))
...

Sheet Cấp 1
A1: Checklist tự đánh giá — HTTT cấp độ 1 (TCVN 14423:2026 mục 3)
A2: Tóm lược để tra cứu; khi lập hồ sơ phải đối chiếu bản chính thức TCVN 14423:2026 (mua tại VSQI). Cột yêu cầu là diễn giải ngắn, không phải nguyên văn tiêu chuẩn.
A4: Nhóm | B4: Tên nhóm | C4: Mục TCVN | D4: Yêu cầu (tóm lược) | E4: Kết quả | F4: Bằng chứng cần lưu | G4: Ghi chú | H4: Người phụ trách | I4: Hạn khắc phục
A5: 3.1 | B5: Quản lý rủi ro an ninh mạng | C5: 3.1 a) | D5: Ban hành quy định/quy trình quản lý rủi ro đủ 4 bước: nhận diện, phân tích, đánh giá, xử lý | F5: Quy trình QLRR đã ký ban hành
A6: 3.1 | B6: Quản lý rủi ro an ninh mạng | C6: 3.1 b) | D6: Rà soát quy trình QLRR và tài liệu kèm theo ≥ 1 lần/năm hoặc khi tổ chức thay đổi | F6: Biên bản rà soát, lịch sử phiên bản
A7: 3.2 | B7: Quản lý tài sản phần cứng | C7: 3.2.1 a) | D7: Danh mục toàn bộ phần cứng của HTTT, kể cả thiết bị bên ngoài có kết nối vào; xác định tài sản cần giám sát | F7: Danh mục tài sản phần cứng
A8: 3.2 | B8: Quản lý tài sản phần cứng | C8: 3.2.1 b) | D8: Phát hiện tài sản vô chủ/trái phép để loại bỏ hoặc đưa vào quản lý | F8: Báo cáo rà soát tài sản
A9: 3.2 | B9: Quản lý tài sản phần cứng | C9: 3.2.1 c) | D9: Kiểm kê, cập nhật danh mục phần cứng ≥ 1 lần/năm | F9: Biên bản kiểm kê
A10: 3.2 | B10: Quản lý tài sản phần cứng | C10: 3.2.2.1 a) | D10: Danh mục phủ mọi thiết bị lưu trữ/xử lý dữ liệu: đầu cuối, di động, lưu trữ ngoài, văn phòng, mạng, OT/IoT, máy chủ vật lý/ảo/cloud | F10: Danh mục tài sản (CMDB/bảng tính)
A11: 3.2 | B11: Quản lý tài sản phần cứng | C11: 3.2.2.1 b) | D11: Trường tối thiểu: tên, IP tĩnh, MAC/serial, hạn hỗ trợ của hãng, vị trí địa lý và trong mạng, mục đích, tình trạng; gán người chịu trách nhiệm | F11: Danh mục có đủ trường, cột người phụ trách
A12: 3.2 | B12: Quản lý tài sản phần cứng | C12: 3.2.2.1 c) | D12: Đăng ký thiết bị di động được phép kết nối; quy định trách nhiệm cá nhân khi dùng cho công việc | F12: Sổ đăng ký thiết bị di động, quy định sử dụng
A13: 3.2 | B13: Quản lý tài sản phần cứng | C13: 3.2.2.2 a) | D13: Quy trình phát hiện, xử lý thiết bị lạ kết nối trái phép, thực hiện ≥ 1 lần/năm | F13: Quy trình + kết quả các lần rà soát
A14: 3.2 | B14: Quản lý tài sản phần cứng | C14: 3.2.2.2 b) | D14: Xử lý thiết bị trái phép bằng cách gỡ bỏ, từ chối kết nối hoặc cách ly | F14: Nhật ký xử lý
A15: 3.3 | B15: Quản lý tài sản phần mềm | C15: 3.3.1 a) | D15: Quản lý danh mục phần mềm; chỉ phần mềm đã phê duyệt mới được cài và dùng | F15: Danh mục phần mềm, quy trình phê duyệt
A16: 3.3 | B16: Quản lý tài sản phần mềm | C16: 3.3.1 b) | D16: Kiểm kê, cập nhật danh mục phần mềm ≥ 1 lần/năm | F16: Biên bản kiểm kê phần mềm
... A113: 3.15 | B113: Quản trị ứng phó sự cố an ninh mạng | C113: 3.15.2.3 b) | D113: Cập nhật quy trình ứng phó ≥ 1 lần/năm hoặc khi thay đổi | F113: Lịch sử phiên bản

Sheet Cấp 2
A1: Checklist tự đánh giá — HTTT cấp độ 2 (TCVN 14423:2026 mục 4)
A2: Tóm lược để tra cứu; khi lập hồ sơ phải đối chiếu bản chính thức TCVN 14423:2026 (mua tại VSQI). Cột yêu cầu là diễn giải ngắn, không phải nguyên văn tiêu chuẩn.
A4: Nhóm | B4: Tên nhóm | C4: Mục TCVN | D4: Yêu cầu (tóm lược) | E4: Kết quả | F4: Bằng chứng cần lưu | G4: Ghi chú | H4: Người phụ trách | I4: Hạn khắc phục
A5: 4.1 | B5: Quản lý rủi ro an ninh mạng | C5: 4.1 a) | D5: Ban hành quy định/quy trình quản lý rủi ro đủ 4 bước: nhận diện, phân tích, đánh giá, xử lý | F5: Quy trình QLRR đã ký ban hành
A6: 4.1 | B6: Quản lý rủi ro an ninh mạng | C6: 4.1 b) | D6: Rà soát quy trình QLRR và tài liệu kèm theo ≥ 1 lần/năm hoặc khi tổ chức thay đổi | F6: Biên bản rà soát, lịch sử phiên bản
A7: 4.2 | B7: Quản lý tài sản phần cứng | C7: 4.2.1 a) | D7: Danh mục toàn bộ phần cứng của HTTT, kể cả thiết bị bên ngoài có kết nối vào; xác định tài sản cần giám sát | F7: Danh mục tài sản phần cứng
A8: 4.2 | B8: Quản lý tài sản phần cứng | C8: 4.2.1 b) | D8: Phát hiện tài sản vô chủ/trái phép để loại bỏ hoặc đưa vào quản lý | F8: Báo cáo rà soát tài sản
A9: 4.2 | B9: Quản lý tài sản phần cứng | C9: 4.2.1 c) | D9: Kiểm kê, cập nhật danh mục tài sản ≥ 1 lần/năm | F9: Biên bản kiểm kê | G9: Mới/khác so với cấp 1
A10: 4.2 | B10: Quản lý tài sản phần cứng | C10: 4.2.2.1 a) | D10: Danh mục phủ mọi thiết bị lưu trữ/xử lý dữ liệu: đầu cuối, di động, lưu trữ ngoài, văn phòng, mạng, OT/IoT, máy chủ vật lý/ảo/cloud | F10: Danh mục tài sản (CMDB/bảng tính)
A11: 4.2 | B11: Quản lý tài sản phần cứng | C11: 4.2.2.1 b) | D11: Trường tối thiểu: tên, IP tĩnh, MAC/serial, hạn hỗ trợ của hãng, vị trí địa lý và trong mạng, mục đích, tình trạng; gán người chịu trách nhiệm | F11: Danh mục có đủ trường, cột người phụ trách
A12: 4.2 | B12: Quản lý tài sản phần cứng | C12: 4.2.2.1 c) | D12: Đăng ký thiết bị di động được phép kết nối; quy định trách nhiệm cá nhân khi dùng cho công việc | F12: Sổ đăng ký thiết bị di động, quy định sử dụng
A13: 4.2 | B13: Quản lý tài sản phần cứng | C13: 4.2.2.2 a) | D13: Quy trình phát hiện, xử lý thiết bị lạ kết nối trái phép, thực hiện ≥ 1 lần/năm | F13: Quy trình + kết quả các lần rà soát
A14: 4.2 | B14: Quản lý tài sản phần cứng | C14: 4.2.2.2 b) | D14: Xử lý thiết bị trái phép bằng cách gỡ bỏ, từ chối kết nối hoặc cách ly | F14: Nhật ký xử lý
A15: 4.2 | B15: Quản lý tài sản phần cứng | C15: 4.2.2.3 | D15: Có phương án xóa sạch dữ liệu khi chuyển giao hoặc đổi mục đích sử dụng phần cứng | F15: Quy trình xóa dữ liệu, biên bản xóa | G15: Mới/khác so với cấp 1
A16: 4.3 | B16: Quản lý tài sản phần mềm | C16: 4.3.1 a) | D16: Quản lý danh mục phần mềm; chỉ phần mềm đã phê duyệt mới được cài và dùng | F16: Danh mục phần mềm, quy trình phê duyệt
A17: 4.3 | B17: Quản lý tài sản phần mềm | C17: 4.3.1 b) | D17: Kiểm kê, cập nhật danh mục phần mềm ≥ 1 lần/năm | F17: Biên bản kiểm kê phần mềm
A18: 4.3 | B18: Quản lý tài sản phần mềm | C18: 4.3.2.1 a) | D18: Lập danh mục phần mềm đang cài trên các thiết bị thuộc HTTT | F18: Danh mục phần mềm (xuất từ công cụ inventory)
A19: 4.3 | B19: Quản lý tài sản phần mềm | C19: 4.3.2.1 b) | D19: Trường tối thiểu: tên, mục đích, hạn hỗ trợ, phạm vi, chủ quản, bản quyền, phiên bản, hệ thống thành phần; gán trách nhiệm | F19: Danh mục có đủ trường
A20: 4.3 | B20: Quản lý tài sản phần mềm | C20: 4.3.2.2 a) | D20: Quy trình phát hiện, xử lý phần mềm trái phép ≥ 1 lần/năm | F20: Quy trình + kết quả rà soát
A21: 4.3 | B21: Quản lý tài sản phần mềm | C21: 4.3.2.2 b) | D21: Phần mềm trái phép nhưng cần thiết đưa vào danh sách ngoại lệ, kèm biện pháp giảm thiểu | F21: Danh sách ngoại lệ có biện pháp kiểm soát
A22: 4.3 | B22: Quản lý tài sản phần mềm | C22: 4.3.2.2 c) | D22: Lập kế hoạch gỡ sớm phần mềm trái phép ngoài danh sách ngoại lệ | F22: Kế hoạch gỡ bỏ, bằng chứng đã gỡ
A23: 4.3 | B23: Quản lý tài sản phần mềm | C23: 4.3.2.3 a) | D23: Phần mềm thuê khoán: có hợp đồng, cam kết bảo mật với bên phát triển | F23: Hợp đồng, NDA | G23: Mới/khác so với cấp 1
A24: 4.3 | B24: Quản lý tài sản phần mềm | C24: 4.3.2.3 b) | D24: Yêu cầu bàn giao mã nguồn; nếu không được thì có chứng chỉ đánh giá độc lập hoặc kiểm thử xâm nhập + cam kết trách nhiệm pháp lý | F24: Biên bản bàn giao mã nguồn/chứng chỉ/cam kết | G24: Mới/khác so với cấp 1
A25: 4.4 | B25: Quản lý tài sản thông tin | C25: 4.4.2.1 a) | D25: Quy định quản lý tài sản thông tin: danh mục, mức nhạy cảm, chủ sở hữu, cách xử lý, thời hạn lưu, yêu cầu tiêu hủy | F25: Quy định quản lý tài sản thông tin
A26: 4.4 | B26: Quản lý tài sản thông tin | C26: 4.4.2.1 b) | D26: Phân loại mức nhạy cảm (gợi ý 3 mức: công khai, nội bộ, hạn chế truy cập) | F26: Bảng phân loại, nhãn dữ liệu | G26: Mới/khác so với cấp 1
A27: 4.4 | B27: Quản lý tài sản thông tin | C27: 4.4.2.1 c) | D27: Quy trình yêu cầu truy cập, thêm, sửa, xóa dữ liệu | F27: Quy trình + phiếu yêu cầu
A28: 4.4 | B28: Quản lý tài sản thông tin | C28: 4.4.2.1 d) | D28: Kiểm tra phân quyền dữ liệu ≥ 1 lần/năm | F28: Biên bản rà soát phân quyền
A29: 4.4 | B29: Quản lý tài sản thông tin | C29: 4.4.2.1 e) | D29: Rà soát quy trình quản lý tài sản thông tin ≥ 1 lần/năm hoặc khi thay đổi | F29: Lịch sử phiên bản quy trình
A30: 4.4 | B30: Quản lý tài sản thông tin | C30: 4.4.2.2 a) | D30: Lập danh mục tài sản thông tin theo quy trình đã ban hành | F30: Danh mục tài sản thông tin
A31: 4.4 | B31: Quản lý tài sản thông tin | C31: 4.4.2.2 b) | D31: Cập nhật danh mục tài sản thông tin ≥ 1 lần/năm hoặc khi thay đổi | F31: Ngày cập nhật danh mục
A32: 4.4 | B32: Quản lý tài sản thông tin | C32: 4.4.2.3 | D32: Ma trận quyền truy cập của từng tài khoản/người dùng với từng loại tài sản thông tin | F32: Ma trận phân quyền (ACL)
A33: 4.4 | B33: Quản lý tài sản thông tin | C33: 4.4.2.4 | D33: Mã hóa thông tin xác thực và dữ liệu không công khai khi lưu (hệ thống truy xuất lớn được dùng biện pháp tương đương) | F33: Cấu hình mã hóa (DB/đĩa/hash mật khẩu) | G33: Mới/khác so với cấp 1
A34: 4.5 | B34: Cấu hình an toàn phần cứng, phần mềm | C34: 4.5.2.1 a) | D34: Ban hành quy định/quy trình cấu hình an toàn cho phần cứng và phần mềm | F34: Quy trình cấu hình an toàn
A35: 4.5 | B35: Cấu hình an toàn phần cứng, phần mềm | C35: 4.5.2.1 b) | D35: Có tài liệu cấu hình chuẩn/hardening; giao thức an toàn; tường lửa host; chống tự động đăng nhập trên tài sản xử lý dữ liệu quan trọng | F35: Baseline cấu hình (vd theo CIS), ảnh chụp cấu hình | G35: Mới/khác so với cấp 1
A36: 4.5 | B36: Cấu hình an toàn phần cứng, phần mềm | C36: 4.5.2.1 c) | D36: Tắt giao thức mạng không an toàn và dịch vụ không dùng | F36: Kết quả quét cổng/dịch vụ | G36: Mới/khác so với cấp 1
A37: 4.5 | B37: Cấu hình an toàn phần cứng, phần mềm | C37: 4.5.2.1 d) | D37: Rà soát quy định và tài liệu cấu hình ≥ 1 lần/năm hoặc khi thay đổi | F37: Lịch sử phiên bản
A38: 4.5 | B38: Cấu hình an toàn phần cứng, phần mềm | C38: 4.5.2.2 a) | D38: Tự khóa phiên theo đánh giá rủi ro — gợi ý: máy người dùng ≤ 15'; phiên quản trị, di động ≤ 5'; phần mềm nghiệp vụ dữ liệu quan trọng ≤ 15' | F38: GPO/MDM/cấu hình timeout | G38: Mới/khác so với cấp 1
A39: 4.5 | B39: Cấu hình an toàn phần cứng, phần mềm | C39: 4.5.2.2 a) | D39: Khóa khi đăng nhập sai — gợi ý: laptop, điện thoại ≤ 10 lần; phần mềm nghiệp vụ dữ liệu quan trọng ≤ 5 lần; khóa 12 giờ–30 ngày | F39: Cấu hình lockout | G39: Mới/khác so với cấp 1
A40: 4.5 | B40: Cấu hình an toàn phần cứng, phần mềm | C40: 4.5.2.2 b) | D40: Có cơ chế mở khóa khẩn cấp cho quản trị viên/tài khoản đặc quyền | F40: Quy trình break-glass
A41: 4.6 | B41: Quản lý tài khoản và quyền truy cập | C41: 4.6.1 a) | D41: Quy trình, công cụ cấp/thu hồi quyền cho 4 loại tài khoản (quản trị, tác nghiệp, kỹ thuật, dịch vụ) theo vai trò | F41: Quy trình quản lý tài khoản
...

Sheet Cấp 3
A1: Checklist tự đánh giá — HTTT cấp độ 3 (TCVN 14423:2026 mục 5)
A2: Tóm lược để tra cứu; khi lập hồ sơ phải đối chiếu bản chính thức TCVN 14423:2026 (mua tại VSQI). Cột yêu cầu là diễn giải ngắn, không phải nguyên văn tiêu chuẩn.
A4: Nhóm | B4: Tên nhóm | C4: Mục TCVN | D4: Yêu cầu (tóm lược) | E4: Kết quả | F4: Bằng chứng cần lưu | G4: Ghi chú | H4: Người phụ trách | I4: Hạn khắc phục
A5: 5.1 | B5: Quản lý rủi ro an ninh mạng | C5: 5.1.2.1 a) | D5: Ban hành quy định/quy trình quản lý rủi ro đủ 4 bước: nhận diện, phân tích, đánh giá, xử lý | F5: Quy trình QLRR đã ký ban hành
A6: 5.1 | B6: Quản lý rủi ro an ninh mạng | C6: 5.1.2.1 b) | D6: Rà soát quy trình QLRR và tài liệu kèm theo ≥ 1 lần/năm hoặc khi tổ chức thay đổi | F6: Biên bản rà soát, lịch sử phiên bản
A7: 5.1 | B7: Quản lý rủi ro an ninh mạng | C7: 5.1.2.2 a) | D7: Nhận diện rủi ro dựa trên tài sản, lỗ hổng, hạ tầng mạng, nhận thức, tài khoản–quyền… | F7: Sổ đăng ký rủi ro (risk register) | G7: Mới/khác so với cấp 2
A8: 5.1 | B8: Quản lý rủi ro an ninh mạng | C8: 5.1.2.2 b) | D8: Nhận diện riêng rủi ro đến từ bên thứ ba, nhà cung cấp | F8: Mục rủi ro bên thứ ba trong risk register | G8: Mới/khác so với cấp 2
A9: 5.1 | B9: Quản lý rủi ro an ninh mạng | C9: 5.1.2.2 c) | D9: Lặp lại nhận diện rủi ro ≥ 1 lần/năm hoặc khi hệ thống thay đổi, có lỗ hổng/sự kiện mới | F9: Risk register có ngày cập nhật | G9: Mới/khác so với cấp 2
A10: 5.1 | B10: Quản lý rủi ro an ninh mạng | C10: 5.1.2.3 a) | D10: Phân tích mức tác động để quyết định chấp nhận hay giảm thiểu từng rủi ro | F10: Bảng đánh giá rủi ro, quyết định xử lý | G10: Mới/khác so với cấp 2
A11: 5.1 | B11: Quản lý rủi ro an ninh mạng | C11: 5.1.2.3 b) | D11: Đánh giá ngay sau khi nhận diện; đánh giá lại khi hệ thống, tổ chức thay đổi hoặc có sự kiện ANM | F11: Lịch sử đánh giá lại | G11: Mới/khác so với cấp 2
A12: 5.1 | B12: Quản lý rủi ro an ninh mạng | C12: 5.1.2.4 a) | D12: Triển khai biện pháp xử lý và lập phương án ứng phó cho rủi ro tồn dư | F12: Kế hoạch xử lý rủi ro, phương án rủi ro tồn dư | G12: Mới/khác so với cấp 2
A13: 5.1 | B13: Quản lý rủi ro an ninh mạng | C13: 5.1.2.4 b) | D13: Đánh giá, cải thiện hiệu quả biện pháp kiểm soát ≥ 1 lần/năm | F13: Báo cáo đánh giá hiệu quả kiểm soát | G13: Mới/khác so với cấp 2
A14: 5.1 | B14: Quản lý rủi ro an ninh mạng | C14: 5.1.2.5 | D14: Theo dõi biến động rủi ro: khả năng xảy ra, tác động, mức rủi ro, tài sản liên quan, biện pháp đã áp dụng | F14: Các cột tương ứng trong risk register | G14: Mới/khác so với cấp 2
A15: 5.1 | B15: Quản lý rủi ro an ninh mạng | C15: 5.1.2.6 | D15: Thông báo kịp thời cho bên liên quan khi rủi ro có thay đổi quan trọng | F15: Thông báo, kênh truyền thông rủi ro | G15: Mới/khác so với cấp 2
A16: 5.2 | B16: Quản lý tài sản phần cứng | C16: 5.2.1 a) | D16: Danh mục toàn bộ phần cứng của HTTT, kể cả thiết bị bên ngoài có kết nối vào; xác định tài sản cần giám sát | F16: Danh mục tài sản phần cứng
A17: 5.2 | B17: Quản lý tài sản phần cứng | C17: 5.2.1 b) | D17: Phát hiện tài sản vô chủ/trái phép để loại bỏ hoặc đưa vào quản lý | F17: Báo cáo rà soát tài sản
A18: 5.2 | B18: Quản lý tài sản phần cứng | C18: 5.2.1 c) | D18: Kiểm kê, cập nhật danh mục tài sản ≥ 1 lần/năm | F18: Biên bản kiểm kê
A19: 5.2 | B19: Quản lý tài sản phần cứng | C19: 5.2.2.1 a) | D19: Danh mục phủ mọi thiết bị lưu trữ/xử lý dữ liệu: đầu cuối, di động, lưu trữ ngoài, văn phòng, mạng, OT/IoT, máy chủ vật lý/ảo/cloud | F19: Danh mục tài sản (CMDB/bảng tính)
A20: 5.2 | B20: Quản lý tài sản phần cứng | C20: 5.2.2.1 b) | D20: Trường tối thiểu: tên, IP tĩnh, MAC/serial, hạn hỗ trợ của hãng, vị trí địa lý và trong mạng, mục đích, tình trạng; gán người chịu trách nhiệm | F20: Danh mục có đủ trường, cột người phụ trách
A21: 5.2 | B21: Quản lý tài sản phần cứng | C21: 5.2.2.1 c) | D21: Đăng ký thiết bị di động được phép kết nối; quy định trách nhiệm cá nhân khi dùng cho công việc | F21: Sổ đăng ký thiết bị di động, quy định sử dụng
A22: 5.2 | B22: Quản lý tài sản phần cứng | C22: 5.2.2.2 a) | D22: Quy trình phát hiện, xử lý thiết bị lạ kết nối trái phép, thực hiện ≥ 1 lần/6 tháng | F22: Quy trình + kết quả các lần rà soát | G22: Mới/khác so với cấp 2
A23: 5.2 | B23: Quản lý tài sản phần cứng | C23: 5.2.2.2 b) | D23: Xử lý thiết bị trái phép bằng cách gỡ bỏ, từ chối kết nối hoặc cách ly | F23: Nhật ký xử lý
A24: 5.2 | B24: Quản lý tài sản phần cứng | C24: 5.2.2.3 | D24: Có phương án xóa sạch dữ liệu khi chuyển giao hoặc đổi mục đích sử dụng phần cứng | F24: Quy trình xóa dữ liệu, biên bản xóa
A25: 5.2 | B25: Quản lý tài sản phần cứng | C25: 5.2.2.4 a) | D25: Bật ghi log DHCP trên mọi máy chủ DHCP/công cụ quản lý IP (nếu có) | F25: Cấu hình log DHCP/IPAM | G25: Mới/khác so với cấp 2
A26: 5.2 | B26: Quản lý tài sản phần cứng | C26: 5.2.2.4 b) | D26: Rà soát log DHCP để cập nhật danh mục ≥ 1 lần/6 tháng | F26: Biên bản rà soát log DHCP | G26: Mới/khác so với cấp 2
A27: 5.3 | B27: Quản lý tài sản phần mềm | C27: 5.3.1 a) | D27: Quản lý danh mục phần mềm; chỉ phần mềm đã phê duyệt mới được cài và dùng | F27: Danh mục phần mềm, quy trình phê duyệt
A28: 5.3 | B28: Quản lý tài sản phần mềm | C28: 5.3.1 b) | D28: Kiểm kê, cập nhật danh mục phần mềm ≥ 1 lần/năm | F28: Biên bản kiểm kê phần mềm
A29: 5.3 | B29: Quản lý tài sản phần mềm | C29: 5.3.2.1 a) | D29: Lập danh mục phần mềm đang cài trên các thiết bị thuộc HTTT | F29: Danh mục phần mềm (xuất từ công cụ inventory)
A30: 5.3 | B30: Quản lý tài sản phần mềm | C30: 5.3.2.1 b) | D30: Trường tối thiểu: tên, mục đích, hạn hỗ trợ, phạm vi, chủ quản, bản quyền, phiên bản, hệ thống thành phần; gán trách nhiệm | F30: Danh mục có đủ trường
A31: 5.3 | B31: Quản lý tài sản phần mềm | C31: 5.3.2.2 a) | D31: Lập danh sách phần mềm được phép sử dụng (whitelist) | F31: Danh sách phần mềm được phép | G31: Mới/khác so với cấp 2
A32: 5.3 | B32: Quản lý tài sản phần mềm | C32: 5.3.2.2 b) | D32: Whitelist gồm cả phần mềm do nhà cung cấp dịch vụ đưa vào và môi trường thực thi của ứng dụng | F32: Whitelist có mục runtime/phần mềm NCC | G32: Mới/khác so với cấp 2
A33: 5.3 | B33: Quản lý tài sản phần mềm | C33: 5.3.2.2 c) | D33: Kiểm soát cài đặt: đặc quyền tối thiểu, chặn cài/gỡ/thực thi trái phép, theo dõi hoạt động cài đặt | F33: Chính sách GPO/MDM/app control, log cài đặt | G33: Mới/khác so với cấp 2
A34: 5.3 | B34: Quản lý tài sản phần mềm | C34: 5.3.2.2 d) | D34: Rà soát whitelist ≥ 1 lần/năm hoặc khi tổ chức thay đổi | F34: Biên bản rà soát whitelist | G34: Mới/khác so với cấp 2
A35: 5.3 | B35: Quản lý tài sản phần mềm | C35: 5.3.2.3 a) | D35: Quy trình phát hiện, xử lý phần mềm trái phép ≥ 1 lần/năm | F35: Quy trình + kết quả rà soát
A36: 5.3 | B36: Quản lý tài sản phần mềm | C36: 5.3.2.3 b) | D36: Phần mềm trái phép nhưng cần thiết đưa vào danh sách ngoại lệ, kèm biện pháp giảm thiểu | F36: Danh sách ngoại lệ có biện pháp kiểm soát
A37: 5.3 | B37: Quản lý tài sản phần mềm | C37: 5.3.2.3 c) | D37: Lập kế hoạch gỡ sớm phần mềm trái phép ngoài danh sách ngoại lệ | F37: Kế hoạch gỡ bỏ, bằng chứng đã gỡ
A38: 5.4 | B38: Quản lý tài sản thông tin | C38: 5.4.2.1 a) | D38: Quy định quản lý tài sản thông tin: danh mục, mức nhạy cảm, chủ sở hữu, cách xử lý, thời hạn lưu, yêu cầu tiêu hủy | F38: Quy định quản lý tài sản thông tin
A39: 5.4 | B39: Quản lý tài sản thông tin | C39: 5.4.2.1 b) | D39: Phân loại mức nhạy cảm (gợi ý 4 mức: công khai, nội bộ, hạn chế, bí mật nhà nước) | F39: Bảng phân loại, nhãn dữ liệu | G39: Mới/khác so với cấp 2
A40: 5.4 | B40: Quản lý tài sản thông tin | C40: 5.4.2.1 c) | D40: Quy trình yêu cầu truy cập, thêm, sửa, xóa dữ liệu | F40: Quy trình + phiếu yêu cầu
A41: 5.4 | B41: Quản lý tài sản thông tin | C41: 5.4.2.1 d) | D41: Kiểm tra phân quyền dữ liệu ≥ 1 lần/6 tháng | F41: Biên bản rà soát phân quyền | G41: Mới/khác so với cấp 2
...

Sheet Cấp 4
A1: Checklist tự đánh giá — HTTT cấp độ 4 (TCVN 14423:2026 mục 6)
A2: Tóm lược để tra cứu; khi lập hồ sơ phải đối chiếu bản chính thức TCVN 14423:2026 (mua tại VSQI). Cột yêu cầu là diễn giải ngắn, không phải nguyên văn tiêu chuẩn.
A4: Nhóm | B4: Tên nhóm | C4: Mục TCVN | D4: Yêu cầu (tóm lược) | E4: Kết quả | F4: Bằng chứng cần lưu | G4: Ghi chú | H4: Người phụ trách | I4: Hạn khắc phục
A5: 6.1 | B5: Quản lý rủi ro an ninh mạng | C5: 6.1.2.1 a) | D5: Ban hành quy định/quy trình quản lý rủi ro đủ 4 bước: nhận diện, phân tích, đánh giá, xử lý | F5: Quy trình QLRR đã ký ban hành
A6: 6.1 | B6: Quản lý rủi ro an ninh mạng | C6: 6.1.2.1 b) | D6: Rà soát quy trình QLRR và tài liệu kèm theo ≥ 1 lần/năm hoặc khi tổ chức thay đổi | F6: Biên bản rà soát, lịch sử phiên bản
A7: 6.1 | B7: Quản lý rủi ro an ninh mạng | C7: 6.1.2.2 a) | D7: Nhận diện rủi ro dựa trên tài sản, lỗ hổng, hạ tầng mạng, nhận thức, tài khoản–quyền… | F7: Sổ đăng ký rủi ro (risk register)
A8: 6.1 | B8: Quản lý rủi ro an ninh mạng | C8: 6.1.2.2 b) | D8: Nhận diện riêng rủi ro đến từ bên thứ ba, nhà cung cấp | F8: Mục rủi ro bên thứ ba trong risk register
A9: 6.1 | B9: Quản lý rủi ro an ninh mạng | C9: 6.1.2.2 c) | D9: Lặp lại nhận diện rủi ro ≥ 1 lần/6 tháng hoặc khi hệ thống thay đổi, có lỗ hổng/sự kiện mới | F9: Risk register có ngày cập nhật | G9: Mới/khác so với cấp 3
A10: 6.1 | B10: Quản lý rủi ro an ninh mạng | C10: 6.1.2.3 a) | D10: Phân tích mức tác động để quyết định chấp nhận hay giảm thiểu từng rủi ro | F10: Bảng đánh giá rủi ro, quyết định xử lý
A11: 6.1 | B11: Quản lý rủi ro an ninh mạng | C11: 6.1.2.3 b) | D11: Đánh giá ngay sau khi nhận diện; đánh giá lại khi hệ thống, tổ chức thay đổi hoặc có sự kiện ANM | F11: Lịch sử đánh giá lại
A12: 6.1 | B12: Quản lý rủi ro an ninh mạng | C12: 6.1.2.4 a) | D12: Triển khai biện pháp xử lý và lập phương án ứng phó cho rủi ro tồn dư | F12: Kế hoạch xử lý rủi ro, phương án rủi ro tồn dư
A13: 6.1 | B13: Quản lý rủi ro an ninh mạng | C13: 6.1.2.4 b) | D13: Đánh giá, cải thiện hiệu quả biện pháp kiểm soát ≥ 1 lần/6 tháng | F13: Báo cáo đánh giá hiệu quả kiểm soát | G13: Mới/khác so với cấp 3
A14: 6.1 | B14: Quản lý rủi ro an ninh mạng | C14: 6.1.2.5 | D14: Theo dõi biến động rủi ro: khả năng xảy ra, tác động, mức rủi ro, tài sản liên quan, biện pháp đã áp dụng | F14: Các cột tương ứng trong risk register
A15: 6.1 | B15: Quản lý rủi ro an ninh mạng | C15: 6.1.2.6 a) | D15: Gửi kết quả đánh giá rủi ro tới những bên có liên quan | F15: Email/biên bản chia sẻ kết quả | G15: Mới/khác so với cấp 3
A16: 6.1 | B16: Quản lý rủi ro an ninh mạng | C16: 6.1.2.6 b) | D16: Thông báo kịp thời cho bên liên quan khi rủi ro có thay đổi quan trọng | F16: Thông báo, kênh truyền thông rủi ro
A17: 6.2 | B17: Quản lý tài sản phần cứng | C17: 6.2.1 a) | D17: Danh mục toàn bộ phần cứng của HTTT, kể cả thiết bị bên ngoài có kết nối vào; xác định tài sản cần giám sát | F17: Danh mục tài sản phần cứng
A18: 6.2 | B18: Quản lý tài sản phần cứng | C18: 6.2.1 b) | D18: Phát hiện tài sản vô chủ/trái phép để loại bỏ hoặc đưa vào quản lý | F18: Báo cáo rà soát tài sản
A19: 6.2 | B19: Quản lý tài sản phần cứng | C19: 6.2.1 c) | D19: Kiểm kê, cập nhật danh mục tài sản ≥ 1 lần/năm | F19: Biên bản kiểm kê
A20: 6.2 | B20: Quản lý tài sản phần cứng | C20: 6.2.2.1 a) | D20: Danh mục phủ mọi thiết bị lưu trữ/xử lý dữ liệu: đầu cuối, di động, lưu trữ ngoài, văn phòng, mạng, OT/IoT, máy chủ vật lý/ảo/cloud | F20: Danh mục tài sản (CMDB/bảng tính)
A21: 6.2 | B21: Quản lý tài sản phần cứng | C21: 6.2.2.1 b) | D21: Kiểm tra an ninh tài sản vật lý trước khi đưa vào sử dụng (theo điều kiện thực tế) | F21: Phiếu kiểm tra thiết bị trước khi sử dụng | G21: Mới/khác so với cấp 3
A22: 6.2 | B22: Quản lý tài sản phần cứng | C22: 6.2.2.1 c) | D22: Trường tối thiểu: tên, IP tĩnh, MAC/serial, hạn hỗ trợ của hãng, vị trí địa lý và trong mạng, mục đích, tình trạng; gán người chịu trách nhiệm | F22: Danh mục có đủ trường, cột người phụ trách
A23: 6.2 | B23: Quản lý tài sản phần cứng | C23: 6.2.2.1 d) | D23: Đăng ký thiết bị di động được phép kết nối; quy định trách nhiệm cá nhân khi dùng cho công việc | F23: Sổ đăng ký thiết bị di động, quy định sử dụng
A24: 6.2 | B24: Quản lý tài sản phần cứng | C24: 6.2.2.2 a) | D24: Quy trình phát hiện, xử lý thiết bị lạ kết nối trái phép, thực hiện ≥ 1 lần/quý | F24: Quy trình + kết quả các lần rà soát | G24: Mới/khác so với cấp 3
A25: 6.2 | B25: Quản lý tài sản phần cứng | C25: 6.2.2.2 b) | D25: Xử lý thiết bị trái phép bằng cách gỡ bỏ, từ chối kết nối hoặc cách ly | F25: Nhật ký xử lý
A26: 6.2 | B26: Quản lý tài sản phần cứng | C26: 6.2.2.3 a) | D26: Quy định rà quét phát hiện tài sản kết nối vào HTTT ≥ 1 lần/quý | F26: Quy định + kết quả quét mạng | G26: Mới/khác so với cấp 3
A27: 6.2 | B27: Quản lý tài sản phần cứng | C27: 6.2.2.3 b) | D27: Cập nhật danh mục tài sản theo kết quả rà quét | F27: Lịch sử cập nhật danh mục | G27: Mới/khác so với cấp 3
A28: 6.2 | B28: Quản lý tài sản phần cứng | C28: 6.2.2.4 a) | D28: Bật ghi log DHCP trên mọi máy chủ DHCP/công cụ quản lý IP (nếu có) | F28: Cấu hình log DHCP/IPAM
A29: 6.2 | B29: Quản lý tài sản phần cứng | C29: 6.2.2.4 b) | D29: Rà soát log DHCP để cập nhật danh mục ≥ 1 lần/quý | F29: Biên bản rà soát log DHCP | G29: Mới/khác so với cấp 3
A30: 6.2 | B30: Quản lý tài sản phần cứng | C30: 6.2.2.5 a) | D30: Có quy trình thanh lý/tiêu hủy tài sản CNTT | F30: Quy trình thanh lý | G30: Mới/khác so với cấp 3
A31: 6.2 | B31: Quản lý tài sản phần cứng | C31: 6.2.2.5 b) | D31: Dùng biện pháp chuyên dụng xóa sạch dữ liệu máy chủ khi chuyển giao/đổi mục đích | F31: Công cụ/biên bản xóa chuyên dụng | G31: Mới/khác so với cấp 3
A32: 6.3 | B32: Quản lý tài sản phần mềm | C32: 6.3.1 a) | D32: Quản lý danh mục phần mềm; chỉ phần mềm đã phê duyệt mới được cài và dùng | F32: Danh mục phần mềm, quy trình phê duyệt
A33: 6.3 | B33: Quản lý tài sản phần mềm | C33: 6.3.1 b) | D33: Kiểm kê, cập nhật danh mục phần mềm ≥ 1 lần/năm | F33: Biên bản kiểm kê phần mềm
A34: 6.3 | B34: Quản lý tài sản phần mềm | C34: 6.3.2.1 a) | D34: Lập danh mục phần mềm đang cài trên các thiết bị thuộc HTTT | F34: Danh mục phần mềm (xuất từ công cụ inventory)
A35: 6.3 | B35: Quản lý tài sản phần mềm | C35: 6.3.2.1 b) | D35: Trường tối thiểu: tên, mục đích, hạn hỗ trợ, phạm vi, chủ quản, bản quyền, phiên bản, hệ thống thành phần; gán trách nhiệm | F35: Danh mục có đủ trường
A36: 6.3 | B36: Quản lý tài sản phần mềm | C36: 6.3.2.2 a) | D36: Lập danh sách phần mềm được phép sử dụng (whitelist) | F36: Danh sách phần mềm được phép
A37: 6.3 | B37: Quản lý tài sản phần mềm | C37: 6.3.2.2 b) | D37: Whitelist gồm cả phần mềm do nhà cung cấp dịch vụ đưa vào và môi trường thực thi của ứng dụng | F37: Whitelist có mục runtime/phần mềm NCC
A38: 6.3 | B38: Quản lý tài sản phần mềm | C38: 6.3.2.2 c) | D38: Kiểm soát cài đặt: đặc quyền tối thiểu, chặn cài/gỡ/thực thi trái phép, theo dõi hoạt động cài đặt | F38: Chính sách GPO/MDM/app control, log cài đặt
A39: 6.3 | B39: Quản lý tài sản phần mềm | C39: 6.3.2.2 d) | D39: Rà soát whitelist ≥ 1 lần/năm hoặc khi tổ chức thay đổi | F39: Biên bản rà soát whitelist
A40: 6.3 | B40: Quản lý tài sản phần mềm | C40: 6.3.2.3 | D40: Đối chiếu whitelist với phần mềm đã cài để bảo đảm còn được hãng hỗ trợ ≥ 1 lần/năm | F40: Báo cáo rà soát EOL | G40: Mới/khác so với cấp 3
A41: 6.3 | B41: Quản lý tài sản phần mềm | C41: 6.3.2.4 a) | D41: Quy trình phát hiện, xử lý phần mềm trái phép ≥ 1 lần/6 tháng | F41: Quy trình + kết quả rà soát | G41: Mới/khác so với cấp 3
...

Sheet Cấp 5
A1: Checklist tự đánh giá — HTTT cấp độ 5 (TCVN 14423:2026 mục 7)
A2: Tóm lược để tra cứu; khi lập hồ sơ phải đối chiếu bản chính thức TCVN 14423:2026 (mua tại VSQI). Cột yêu cầu là diễn giải ngắn, không phải nguyên văn tiêu chuẩn.
A4: Nhóm | B4: Tên nhóm | C4: Mục TCVN | D4: Yêu cầu (tóm lược) | E4: Kết quả | F4: Bằng chứng cần lưu | G4: Ghi chú | H4: Người phụ trách | I4: Hạn khắc phục
A5: 7.1 | B5: Quản lý rủi ro an ninh mạng | C5: 7.1.2.1 a) | D5: Ban hành quy định/quy trình quản lý rủi ro đủ 4 bước: nhận diện, phân tích, đánh giá, xử lý | F5: Quy trình QLRR đã ký ban hành
A6: 7.1 | B6: Quản lý rủi ro an ninh mạng | C6: 7.1.2.1 b) | D6: Rà soát quy trình QLRR và tài liệu kèm theo ≥ 1 lần/6 tháng hoặc khi tổ chức thay đổi | F6: Biên bản rà soát, lịch sử phiên bản | G6: Mới/khác so với cấp 4
A7: 7.1 | B7: Quản lý rủi ro an ninh mạng | C7: 7.1.2.2 a) | D7: Nhận diện rủi ro dựa trên tài sản, lỗ hổng, hạ tầng mạng, nhận thức, tài khoản–quyền… | F7: Sổ đăng ký rủi ro (risk register)
A8: 7.1 | B8: Quản lý rủi ro an ninh mạng | C8: 7.1.2.2 b) | D8: Nhận diện riêng rủi ro đến từ bên thứ ba, nhà cung cấp | F8: Mục rủi ro bên thứ ba trong risk register
A9: 7.1 | B9: Quản lý rủi ro an ninh mạng | C9: 7.1.2.2 c) | D9: Lặp lại nhận diện rủi ro ≥ 1 lần/6 tháng hoặc khi hệ thống thay đổi, có lỗ hổng/sự kiện mới | F9: Risk register có ngày cập nhật
A10: 7.1 | B10: Quản lý rủi ro an ninh mạng | C10: 7.1.2.3 a) | D10: Phân tích mức tác động để quyết định chấp nhận hay giảm thiểu từng rủi ro | F10: Bảng đánh giá rủi ro, quyết định xử lý
A11: 7.1 | B11: Quản lý rủi ro an ninh mạng | C11: 7.1.2.3 b) | D11: Đánh giá ngay sau khi nhận diện; đánh giá lại khi hệ thống, tổ chức thay đổi hoặc có sự kiện ANM | F11: Lịch sử đánh giá lại
A12: 7.1 | B12: Quản lý rủi ro an ninh mạng | C12: 7.1.2.4 a) | D12: Triển khai biện pháp xử lý và lập phương án ứng phó cho rủi ro tồn dư | F12: Kế hoạch xử lý rủi ro, phương án rủi ro tồn dư
A13: 7.1 | B13: Quản lý rủi ro an ninh mạng | C13: 7.1.2.4 b) | D13: Đánh giá, cải thiện hiệu quả biện pháp kiểm soát ≥ 1 lần/6 tháng | F13: Báo cáo đánh giá hiệu quả kiểm soát
A14: 7.1 | B14: Quản lý rủi ro an ninh mạng | C14: 7.1.2.5 | D14: Theo dõi biến động rủi ro: khả năng xảy ra, tác động, mức rủi ro, tài sản liên quan, biện pháp đã áp dụng | F14: Các cột tương ứng trong risk register
A15: 7.1 | B15: Quản lý rủi ro an ninh mạng | C15: 7.1.2.6 a) | D15: Gửi kết quả đánh giá rủi ro tới những bên có liên quan | F15: Email/biên bản chia sẻ kết quả
A16: 7.1 | B16: Quản lý rủi ro an ninh mạng | C16: 7.1.2.6 b) | D16: Thông báo kịp thời cho bên liên quan khi rủi ro có thay đổi quan trọng | F16: Thông báo, kênh truyền thông rủi ro
A17: 7.2 | B17: Quản lý tài sản phần cứng | C17: 7.2.1 a) | D17: Danh mục toàn bộ phần cứng của HTTT, kể cả thiết bị bên ngoài có kết nối vào; xác định tài sản cần giám sát | F17: Danh mục tài sản phần cứng
A18: 7.2 | B18: Quản lý tài sản phần cứng | C18: 7.2.1 b) | D18: Phát hiện tài sản vô chủ/trái phép để loại bỏ hoặc đưa vào quản lý | F18: Báo cáo rà soát tài sản
A19: 7.2 | B19: Quản lý tài sản phần cứng | C19: 7.2.1 c) | D19: Kiểm kê, cập nhật danh mục tài sản ≥ 1 lần/6 tháng | F19: Biên bản kiểm kê | G19: Mới/khác so với cấp 4
A20: 7.2 | B20: Quản lý tài sản phần cứng | C20: 7.2.2.1 a) | D20: Danh mục phủ mọi thiết bị lưu trữ/xử lý dữ liệu: đầu cuối, di động, lưu trữ ngoài, văn phòng, mạng, OT/IoT, máy chủ vật lý/ảo/cloud | F20: Danh mục tài sản (CMDB/bảng tính)
A21: 7.2 | B21: Quản lý tài sản phần cứng | C21: 7.2.2.1 b) | D21: Kiểm tra an ninh tài sản vật lý trước khi đưa vào sử dụng (theo điều kiện thực tế) | F21: Phiếu kiểm tra thiết bị trước khi sử dụng
A22: 7.2 | B22: Quản lý tài sản phần cứng | C22: 7.2.2.1 c) | D22: Trường tối thiểu: tên, IP tĩnh, MAC/serial, hạn hỗ trợ của hãng, vị trí địa lý và trong mạng, mục đích, tình trạng; gán người chịu trách nhiệm | F22: Danh mục có đủ trường, cột người phụ trách
A23: 7.2 | B23: Quản lý tài sản phần cứng | C23: 7.2.2.1 d) | D23: Đăng ký thiết bị di động được phép kết nối; quy định trách nhiệm cá nhân khi dùng cho công việc | F23: Sổ đăng ký thiết bị di động, quy định sử dụng
A24: 7.2 | B24: Quản lý tài sản phần cứng | C24: 7.2.2.2 a) | D24: Quy trình phát hiện, xử lý thiết bị lạ kết nối trái phép, thực hiện ≥ 1 lần/tháng | F24: Quy trình + kết quả các lần rà soát | G24: Mới/khác so với cấp 4
A25: 7.2 | B25: Quản lý tài sản phần cứng | C25: 7.2.2.2 b) | D25: Xử lý thiết bị trái phép bằng cách gỡ bỏ, từ chối kết nối hoặc cách ly | F25: Nhật ký xử lý
A26: 7.2 | B26: Quản lý tài sản phần cứng | C26: 7.2.2.3 a) | D26: Quy định rà quét phát hiện tài sản kết nối vào HTTT ≥ 1 lần/tháng | F26: Quy định + kết quả quét mạng | G26: Mới/khác so với cấp 4
A27: 7.2 | B27: Quản lý tài sản phần cứng | C27: 7.2.2.3 b) | D27: Cập nhật danh mục tài sản theo kết quả rà quét | F27: Lịch sử cập nhật danh mục
A28: 7.2 | B28: Quản lý tài sản phần cứng | C28: 7.2.2.4 a) | D28: Bật ghi log DHCP trên mọi máy chủ DHCP/công cụ quản lý IP (nếu có) | F28: Cấu hình log DHCP/IPAM
A29: 7.2 | B29: Quản lý tài sản phần cứng | C29: 7.2.2.4 b) | D29: Rà soát log DHCP để cập nhật danh mục ≥ 1 lần/tháng | F29: Biên bản rà soát log DHCP | G29: Mới/khác so với cấp 4
A30: 7.2 | B30: Quản lý tài sản phần cứng | C30: 7.2.2.5 a) | D30: Có quy trình thanh lý/tiêu hủy tài sản CNTT | F30: Quy trình thanh lý
A31: 7.2 | B31: Quản lý tài sản phần cứng | C31: 7.2.2.5 b) | D31: Dùng biện pháp chuyên dụng xóa sạch dữ liệu máy chủ khi chuyển giao/đổi mục đích | F31: Công cụ/biên bản xóa chuyên dụng
A32: 7.2 | B32: Quản lý tài sản phần cứng | C32: 7.2.2.5 c) | D32: Sao lưu dữ liệu và bản dự phòng HĐH máy chủ trước khi xóa | F32: Bản sao lưu trước khi xóa | G32: Mới/khác so với cấp 4
A33: 7.2 | B33: Quản lý tài sản phần cứng | C33: 7.2.2.5 d) | D33: Kiểm chứng dữ liệu đã xóa không thể khôi phục | F33: Biên bản kiểm tra sau xóa | G33: Mới/khác so với cấp 4
A34: 7.3 | B34: Quản lý tài sản phần mềm | C34: 7.3.1 a) | D34: Quản lý danh mục phần mềm; chỉ phần mềm đã phê duyệt mới được cài và dùng | F34: Danh mục phần mềm, quy trình phê duyệt
A35: 7.3 | B35: Quản lý tài sản phần mềm | C35: 7.3.1 b) | D35: Kiểm kê, cập nhật danh mục phần mềm ≥ 1 lần/6 tháng | F35: Biên bản kiểm kê phần mềm | G35: Mới/khác so với cấp 4
A36: 7.3 | B36: Quản lý tài sản phần mềm | C36: 7.3.2.1 a) | D36: Lập danh mục phần mềm đang cài trên các thiết bị thuộc HTTT | F36: Danh mục phần mềm (xuất từ công cụ inventory)
A37: 7.3 | B37: Quản lý tài sản phần mềm | C37: 7.3.2.1 b) | D37: Trường tối thiểu: tên, mục đích, hạn hỗ trợ, phạm vi, chủ quản, bản quyền, phiên bản, hệ thống thành phần; gán trách nhiệm | F37: Danh mục có đủ trường
A38: 7.3 | B38: Quản lý tài sản phần mềm | C38: 7.3.2.2 a) | D38: Lập danh sách phần mềm được phép sử dụng (whitelist) | F38: Danh sách phần mềm được phép
A39: 7.3 | B39: Quản lý tài sản phần mềm | C39: 7.3.2.2 b) | D39: Whitelist gồm cả phần mềm do nhà cung cấp dịch vụ đưa vào và môi trường thực thi của ứng dụng | F39: Whitelist có mục runtime/phần mềm NCC
A40: 7.3 | B40: Quản lý tài sản phần mềm | C40: 7.3.2.2 c) | D40: Kiểm soát cài đặt: đặc quyền tối thiểu, chặn cài/gỡ/thực thi trái phép, theo dõi hoạt động cài đặt | F40: Chính sách GPO/MDM/app control, log cài đặt
A41: 7.3 | B41: Quản lý tài sản phần mềm | C41: 7.3.2.2 d) | D41: Rà soát whitelist ≥ 1 lần/6 tháng hoặc khi tổ chức thay đổi | F41: Biên bản rà soát whitelist | G41: Mới/khác so với cấp 4
...
